Workbook

Sheet 요구사항 정리표
B2: 반려동물 종합 플랫폼 요구사항 정리표
B4: ="전체 요구사항: "&COUNTA(B6:B993)&"건" -> 전체 요구사항: 69건 | D4: =COUNTIF(H6:H993,"완료")&"건 완료" -> 69건 완료 | F4: =COUNTIF(H6:H993,"진행중")&"건 진행중" -> 0건 진행중 | H4: =COUNTIF(H6:H993,"대기")&"건 대기" -> 0건 대기 | J4: =IF(COUNTA(B6:B993)=0, "0.0% 완료", TEXT(COUNTIF(H6:H993, "완료")/COUNTA(B6:B993), "0.0%")&" 완료") -> 100.0% 완료
B5: 요구사항 ID | C5: 대분류 | D5: 상세 분류 | E5: 요구사항 명 | F5: 상세 설명 | G5: 중요도 | H5: 진행 상태 | I5: 권한 | J5: 비고
B6: REQ-001 | C6: 공통/인증 | D6: 계정 | E6: 회원가입 | F6: 이메일·비밀번호(BCrypt) 가입, 활성 회원 기준 이메일 중복 검사(lower 기준) | G6: 높음 | H6: 완료 | I6: 전체
B7: REQ-002 | C7: 공통/인증 | D7: 계정 | E7: 로그인 | F7: JWT 액세스 토큰(15분, HS512) 발급 | G7: 높음 | H7: 완료 | I7: 전체
B8: REQ-003 | C8: 공통/인증 | D8: 계정 | E8: 리프레시 토큰 | F8: DB 해시 저장+HttpOnly 쿠키(14일), 회전·재사용 감지 시 전체 폐기 | G8: 높음 | H8: 완료 | I8: 전체
B9: REQ-004 | C9: 공통/인증 | D9: 계정 | E9: 액세스 토큰 자동 재발급 | F9: 401 시 /refresh 후 원요청 재시도, 동시 요청도 재발급 1회로 묶음 | G9: 높음 | H9: 완료 | I9: 회원
B10: REQ-005 | C10: 공통/인증 | D10: 계정 | E10: 카카오 로그인 | F10: 인가 코드 교환·자동 가입, 이메일 미제공 허용, 임의 닉네임 생성 | G10: 높음 | H10: 완료 | I10: 전체
B11: REQ-006 | C11: 공통/인증 | D11: 계정 | E11: 비밀번호 변경 | F11: 현재 비밀번호 확인, 타 기기 토큰 전체 폐기+현재 기기 재발급 | G11: 높음 | H11: 완료 | I11: 회원
B12: REQ-007 | C12: 공통/인증 | D12: 계정 | E12: 닉네임 수정·중복 방지 | F12: 활성 회원 기준 lower(name) 유니크(DB 백스톱 인덱스) | G12: 중간 | H12: 완료 | I12: 회원
B13: REQ-008 | C13: 공통/인증 | D13: 계정 | E13: 회원 프로필 사진 | F13: Storage 업로드(고정 경로 upsert+캐시버스터), 브라우저 리사이징 | G13: 중간 | H13: 완료 | I13: 회원
B14: REQ-009 | C14: 공통/인증 | D14: 보안 | E14: 로그인 기기 관리 | F14: 기기 목록(UA 파싱)·원격 로그아웃, 현재 세션 폐기 거부(400) | G14: 중간 | H14: 완료 | I14: 회원
B15: REQ-010 | C15: 공통/인증 | D15: 계정 | E15: 회원 탈퇴 | F15: 소프트 삭제+전 토큰 폐기, 방장 방 보유 시 409 거부 | G15: 높음 | H15: 완료 | I15: 회원
B16: REQ-011 | C16: 공통/인증 | D16: 계정 | E16: 공개 회원 프로필 | F16: GET /members/{id}/profile — 이름·사진 공개 조회 | G16: 중간 | H16: 완료 | I16: 회원
B17: REQ-012 | C17: 공통/인증 | D17: 권한 | E17: 소유자 데이터 격리 | F17: 본인 반려동물만 접근, 타인·삭제·없음 모두 404로 통일 | G17: 높음 | H17: 완료 | I17: 회원
... B21: REQ-016 | C21: 공통/인프라 | D21: 인프라 | E21: CORS·쿠키 계약 | F21: 오리진 단일 출처화(CORS_ALLOWED_ORIGINS), credentials 포함 | G21: 높음 | H21: 완료 | I21: 전체
B22: REQ-017 | C22: 공통/인프라 | D22: 배포 | E22: EC2 배포+CI/CD | F22: EC2+nginx+systemd, GitHub Actions main push 자동 배포 | G22: 높음 | H22: 완료 | I22: 전체 | J22: dddang.duckdns.org
B23: REQ-018 | C23: 공통/인프라 | D23: 배포 | E23: HTTPS | F23: duckdns 도메인+인증서, WS 프록시·SPA fallback | G23: 높음 | H23: 완료 | I23: 전체
B24: REQ-019 | C24: 공통/인프라 | D24: 배치 | E24: 만료 토큰 정리 | F24: 만료 7일 경과 리프레시 토큰 삭제(04:30), 폐기 행은 보존 | G24: 낮음 | H24: 완료 | I24: 전체
B25: REQ-021 | C25: 반려동물 | D25: 펫 | E25: 펫 등록 | F25: 이름·품종·생일 등록, 등록 시 사진 첨부(등록→업로드 2단계 연계) | G25: 높음 | H25: 완료 | I25: 회원
B26: REQ-022 | C26: 반려동물 | D26: 펫 | E26: 펫 목록 | F26: 홈 목록·썸네일, sort_order ASC→최근 등록순 정렬 | G26: 높음 | H26: 완료 | I26: 회원
B27: REQ-023 | C27: 반려동물 | D27: 펫 | E27: 펫 상세·수정·삭제 | F27: PUT 전체 교체, 소프트 삭제, 낙관적 잠금(@Version) | G27: 높음 | H27: 완료 | I27: 회원
B28: REQ-024 | C28: 반려동물 | D28: 펫 | E28: 펫 프로필 사진 | F28: Storage 업로드+리사이징, 미등록 시 placeholder | G28: 중간 | H28: 완료 | I28: 회원
B29: REQ-025 | C29: 반려동물 | D29: 펫 | E29: 노출 순서 저장 | F29: PUT /pets/order — 홈 노출 순서 지정 | G29: 낮음 | H29: 완료 | I29: 회원
B30: REQ-026 | C30: 반려동물 | D30: 온보딩 | E30: 가입 직후 등록 유도 | F30: 가입→자동 로그인→/welcome 1회 노출 | G30: 중간 | H30: 완료 | I30: 회원
B31: REQ-027 | C31: 반려동물 | D31: 펫 | E31: 홈 펫 프로필 노출 | F31: 홈 상단 펫 카드(노출 개수 제한) | G31: 중간 | H31: 완료 | I31: 회원
B32: REQ-028 | C32: 오픈채팅 | D32: 방 | E32: 방 생성 | F32: 누구나 생성, 카테고리(산책·훈련·건강·자유)·정원(2~100)·소개 입력 | G32: 높음 | H32: 완료 | I32: 회원
B33: REQ-029 | C33: 오픈채팅 | D33: 방 | E33: 방 목록·검색·필터 | F33: keyword(이름+소개 ILIKE)·카테고리·참여자순 정렬 | G33: 높음 | H33: 완료 | I33: 회원
B34: REQ-030 | C34: 오픈채팅 | D34: 방 | E34: 입장·나가기 | F34: 정원 검사 409, 강퇴 이력 재입장 차단 | G34: 높음 | H34: 완료 | I34: 회원
... B51: REQ-047 | C51: AI 진단 | D51: 연계 | E51: 진단 후 병원 안내 | F51: 진단 결과에서 주변 동물병원 지도 노출 | G51: 중간 | H51: 완료 | I51: 회원
B52: REQ-048 | C52: AI 진단 | D52: 서빙 | E52: 모델 서버 배포 | F52: FastAPI 모델 서버 별도 배포(1차 배포 제외) | G52: 중간 | H52: 완료 | I52: 전체 | J52: AI_SERVER_URL 미연결
B53: REQ-049 | C53: 지도 | D53: 장소 | E53: 주변 장소 검색 | F53: 카카오 장소 API — 병원·카페·미용샵 등 카테고리 | G53: 높음 | H53: 완료 | I53: 회원
B54: REQ-050 | C54: 지도 | D54: 장소 | E54: 현위치 이동 | F54: 초기 진입 내 위치, 재검색 시 축척 유지 | G54: 중간 | H54: 완료 | I54: 회원
B55: REQ-051 | C55: 지도 | D55: AI | E55: AI 장소 추천 | F55: 챗봇 tool use+장소 검색 결합(/api/ai-search) | G55: 중간 | H55: 완료 | I55: 회원
B56: REQ-052 | C56: 지도 | D56: UI | E56: 지도 모바일 UI | F56: 360px 모바일 퍼스트, 오버레이·토스트 | G56: 중간 | H56: 완료 | I56: 회원
B57: REQ-053 | C57: 산책 | D57: 산책 | E57: 산책로 정보 | F57: 산책로 추가·조회 | G57: 중간 | H57: 완료 | I57: 회원
B58: REQ-054 | C58: 산책 | D58: 산책 | E58: 산책 기록 | F58: walk_record 기록 저장·조회 | G58: 중간 | H58: 완료 | I58: 회원
B59: REQ-055 | C59: 산책 | D59: 산책 | E59: 산책 알림 | F59: 산책 알림 발송 | G59: 중간 | H59: 완료 | I59: 회원
B60: REQ-056 | C60: 숏츠 | D60: 숏츠 | E60: 영상 업로드 | F60: Storage shorts 버킷 업로드 | G60: 높음 | H60: 완료 | I60: 회원
B61: REQ-057 | C61: 숏츠 | D61: 숏츠 | E61: 피드 | F61: 피드 정렬 알고리즘, 비로그인 열람 가능 | G61: 높음 | H61: 완료 | I61: 전체
...

Sheet 대분류별 집계
B2: 대분류별 요구사항 집계
B4: 대분류 | C4: 전체 | D4: 완료 | E4: 진행중 | F4: 대기 | G4: 완료율
B5: 공통/인증 | C5: =COUNTIF('요구사항 정리표'!$C$6:$C$74,$B5) -> 12 | D5: =COUNTIFS('요구사항 정리표'!$C$6:$C$74,$B5,'요구사항 정리표'!$H$6:$H$74,"완료") -> 12 | E5: =COUNTIFS('요구사항 정리표'!$C$6:$C$74,$B5,'요구사항 정리표'!$H$6:$H$74,"진행중") -> 0 | F5: =COUNTIFS('요구사항 정리표'!$C$6:$C$74,$B5,'요구사항 정리표'!$H$6:$H$74,"대기") -> 0 | G5: =IF(C5=0,0,D5/C5) -> 1
B6: 공통/인프라 | C6: =COUNTIF('요구사항 정리표'!$C$6:$C$74,$B6) -> 7 | D6: =COUNTIFS('요구사항 정리표'!$C$6:$C$74,$B6,'요구사항 정리표'!$H$6:$H$74,"완료") -> 7 | E6: =COUNTIFS('요구사항 정리표'!$C$6:$C$74,$B6,'요구사항 정리표'!$H$6:$H$74,"진행중") -> 0 | F6: =COUNTIFS('요구사항 정리표'!$C$6:$C$74,$B6,'요구사항 정리표'!$H$6:$H$74,"대기") -> 0 | G6: =IF(C6=0,0,D6/C6) -> 1
B7: 반려동물 | C7: =COUNTIF('요구사항 정리표'!$C$6:$C$74,$B7) -> 7 | D7: =COUNTIFS('요구사항 정리표'!$C$6:$C$74,$B7,'요구사항 정리표'!$H$6:$H$74,"완료") -> 7 | E7: =COUNTIFS('요구사항 정리표'!$C$6:$C$74,$B7,'요구사항 정리표'!$H$6:$H$74,"진행중") -> 0 | F7: =COUNTIFS('요구사항 정리표'!$C$6:$C$74,$B7,'요구사항 정리표'!$H$6:$H$74,"대기") -> 0 | G7: =IF(C7=0,0,D7/C7) -> 1
B8: 오픈채팅 | C8: =COUNTIF('요구사항 정리표'!$C$6:$C$74,$B8) -> 15 | D8: =COUNTIFS('요구사항 정리표'!$C$6:$C$74,$B8,'요구사항 정리표'!$H$6:$H$74,"완료") -> 15 | E8: =COUNTIFS('요구사항 정리표'!$C$6:$C$74,$B8,'요구사항 정리표'!$H$6:$H$74,"진행중") -> 0 | F8: =COUNTIFS('요구사항 정리표'!$C$6:$C$74,$B8,'요구사항 정리표'!$H$6:$H$74,"대기") -> 0 | G8: =IF(C8=0,0,D8/C8) -> 1
B9: AI 진단 | C9: =COUNTIF('요구사항 정리표'!$C$6:$C$74,$B9) -> 6 | D9: =COUNTIFS('요구사항 정리표'!$C$6:$C$74,$B9,'요구사항 정리표'!$H$6:$H$74,"완료") -> 6 | E9: =COUNTIFS('요구사항 정리표'!$C$6:$C$74,$B9,'요구사항 정리표'!$H$6:$H$74,"진행중") -> 0 | F9: =COUNTIFS('요구사항 정리표'!$C$6:$C$74,$B9,'요구사항 정리표'!$H$6:$H$74,"대기") -> 0 | G9: =IF(C9=0,0,D9/C9) -> 1
B10: 지도 | C10: =COUNTIF('요구사항 정리표'!$C$6:$C$74,$B10) -> 4 | D10: =COUNTIFS('요구사항 정리표'!$C$6:$C$74,$B10,'요구사항 정리표'!$H$6:$H$74,"완료") -> 4 | E10: =COUNTIFS('요구사항 정리표'!$C$6:$C$74,$B10,'요구사항 정리표'!$H$6:$H$74,"진행중") -> 0 | F10: =COUNTIFS('요구사항 정리표'!$C$6:$C$74,$B10,'요구사항 정리표'!$H$6:$H$74,"대기") -> 0 | G10: =IF(C10=0,0,D10/C10) -> 1
B11: 산책 | C11: =COUNTIF('요구사항 정리표'!$C$6:$C$74,$B11) -> 3 | D11: =COUNTIFS('요구사항 정리표'!$C$6:$C$74,$B11,'요구사항 정리표'!$H$6:$H$74,"완료") -> 3 | E11: =COUNTIFS('요구사항 정리표'!$C$6:$C$74,$B11,'요구사항 정리표'!$H$6:$H$74,"진행중") -> 0 | F11: =COUNTIFS('요구사항 정리표'!$C$6:$C$74,$B11,'요구사항 정리표'!$H$6:$H$74,"대기") -> 0 | G11: =IF(C11=0,0,D11/C11) -> 1
B12: 숏츠 | C12: =COUNTIF('요구사항 정리표'!$C$6:$C$74,$B12) -> 6 | D12: =COUNTIFS('요구사항 정리표'!$C$6:$C$74,$B12,'요구사항 정리표'!$H$6:$H$74,"완료") -> 6 | E12: =COUNTIFS('요구사항 정리표'!$C$6:$C$74,$B12,'요구사항 정리표'!$H$6:$H$74,"진행중") -> 0 | F12: =COUNTIFS('요구사항 정리표'!$C$6:$C$74,$B12,'요구사항 정리표'!$H$6:$H$74,"대기") -> 0 | G12: =IF(C12=0,0,D12/C12) -> 1
B13: 광고 | C13: =COUNTIF('요구사항 정리표'!$C$6:$C$74,$B13) -> 2 | D13: =COUNTIFS('요구사항 정리표'!$C$6:$C$74,$B13,'요구사항 정리표'!$H$6:$H$74,"완료") -> 2 | E13: =COUNTIFS('요구사항 정리표'!$C$6:$C$74,$B13,'요구사항 정리표'!$H$6:$H$74,"진행중") -> 0 | F13: =COUNTIFS('요구사항 정리표'!$C$6:$C$74,$B13,'요구사항 정리표'!$H$6:$H$74,"대기") -> 0 | G13: =IF(C13=0,0,D13/C13) -> 1
B14: AI 비서 | C14: =COUNTIF('요구사항 정리표'!$C$6:$C$74,$B14) -> 2 | D14: =COUNTIFS('요구사항 정리표'!$C$6:$C$74,$B14,'요구사항 정리표'!$H$6:$H$74,"완료") -> 2 | E14: =COUNTIFS('요구사항 정리표'!$C$6:$C$74,$B14,'요구사항 정리표'!$H$6:$H$74,"진행중") -> 0 | F14: =COUNTIFS('요구사항 정리표'!$C$6:$C$74,$B14,'요구사항 정리표'!$H$6:$H$74,"대기") -> 0 | G14: =IF(C14=0,0,D14/C14) -> 1
B15: UI/홈 | C15: =COUNTIF('요구사항 정리표'!$C$6:$C$74,$B15) -> 5 | D15: =COUNTIFS('요구사항 정리표'!$C$6:$C$74,$B15,'요구사항 정리표'!$H$6:$H$74,"완료") -> 5 | E15: =COUNTIFS('요구사항 정리표'!$C$6:$C$74,$B15,'요구사항 정리표'!$H$6:$H$74,"진행중") -> 0 | F15: =COUNTIFS('요구사항 정리표'!$C$6:$C$74,$B15,'요구사항 정리표'!$H$6:$H$74,"대기") -> 0 | G15: =IF(C15=0,0,D15/C15) -> 1
B16: 디바이스 | C16: =COUNTIF('요구사항 정리표'!$C$6:$C$74,$B16) -> 0 | D16: =COUNTIFS('요구사항 정리표'!$C$6:$C$74,$B16,'요구사항 정리표'!$H$6:$H$74,"완료") -> 0 | E16: =COUNTIFS('요구사항 정리표'!$C$6:$C$74,$B16,'요구사항 정리표'!$H$6:$H$74,"진행중") -> 0 | F16: =COUNTIFS('요구사항 정리표'!$C$6:$C$74,$B16,'요구사항 정리표'!$H$6:$H$74,"대기") -> 0 | G16: =IF(C16=0,0,D16/C16) -> 0
B17: 게시판 | C17: =COUNTIF('요구사항 정리표'!$C$6:$C$74,$B17) -> 0 | D17: =COUNTIFS('요구사항 정리표'!$C$6:$C$74,$B17,'요구사항 정리표'!$H$6:$H$74,"완료") -> 0 | E17: =COUNTIFS('요구사항 정리표'!$C$6:$C$74,$B17,'요구사항 정리표'!$H$6:$H$74,"진행중") -> 0 | F17: =COUNTIFS('요구사항 정리표'!$C$6:$C$74,$B17,'요구사항 정리표'!$H$6:$H$74,"대기") -> 0 | G17: =IF(C17=0,0,D17/C17) -> 0
B18: 합계 | C18: =SUM(C5:C17) -> 69 | D18: =SUM(D5:D17) -> 69 | E18: =SUM(E5:E17) -> 0 | F18: =SUM(F5:F17) -> 0 | G18: =IF(C18=0,0,D18/C18) -> 1
B20: ※ 진행 상태는 pet_project 코드·설계 문서(roadmap.md, api-spec.md, schema.sql) 및 git 커밋 이력(2026-09-01 기준)을 근거로 작성했습니다.
